<?xml version="1.0" ?>
<robot name="f-adrt">
  <joint name="f-adrt__link_5_JOINT_4" type="revolute">
    <parent link="f-adrt__link_5"/>
    <child link="f-adrt__link_6"/>
    <origin rpy="1.5707  0      0" xyz="0.55    -0.62502  0"/>
    <axis xyz="0.00000000e+00   1.00000000e+00   9.00000000e-05"/>
    <limit effort="-1.0" lower="-1.79769e+308" upper="1.79769e+308" velocity="-1.0"/>
  </joint>
  <joint name="f-adrt__link_5_JOINT_5" type="revolute">
    <parent link="f-adrt__link_5"/>
    <child link="f-adrt__link_6_clone"/>
    <origin rpy="1.5707  0      0" xyz="0.55     0.62502  0"/>
    <axis xyz="0.00000000e+00   1.00000000e+00   9.00000000e-05"/>
    <limit effort="-1.0" lower="-1.79769e+308" upper="1.79769e+308" velocity="-1.0"/>
  </joint>

  <link name="f-adrt__link_5">
    <inertial>
      <mass value="1"/>
      <origin rpy="0  0  0" xyz="0  0  0"/>
      <inertia ixx="0.166667" ixy="0" ixz="0" iyy="0.166667" iyz="0" izz="0.166667"/>
    </inertial>
    <collision name="f-adrt__collision">
      <origin rpy="0  0  0" xyz="-0.15  0    0.1"/>
      <geometry>
        <box size="2 1 0.5"/>
      </geometry>
    </collision>
    <visual name="f-adrt__visual">
      <origin rpy="0  0  0" xyz="-0.15  0    0.1"/>
      <geometry>
        <box size="2 1 0.5"/>
      </geometry>
    </visual>
  </link>
  <link name="f-adrt__link_6">
    <inertial>
      <mass value="1"/>
      <origin rpy="0  0  0" xyz="0  0  0"/>
      <inertia ixx="0.145833" ixy="0" ixz="0" iyy="0.145833" iyz="0" izz="0.125"/>
    </inertial>
    <collision name="f-adrt__collision">
      <origin rpy="0  0  0" xyz="0  0  0"/>
      <geometry>
        <cylinder length="0.25" radius="0.3"/>
      </geometry>
    </collision>
    <visual name="f-adrt__visual">
      <origin rpy="0  0  0" xyz="0  0  0"/>
      <geometry>
        <cylinder length="0.25" radius="0.3"/>
      </geometry>
    </visual>
  </link>
  <link name="f-adrt__link_6_clone">
    <inertial>
      <mass value="1"/>
      <origin rpy="0  0  0" xyz="0  0  0"/>
      <inertia ixx="0.145833" ixy="0" ixz="0" iyy="0.145833" iyz="0" izz="0.125"/>
    </inertial>
    <collision name="f-adrt__collision">
      <origin rpy="0  0  0" xyz="0  0  0"/>
      <geometry>
        <cylinder length="0.25" radius="0.3"/>
      </geometry>
    </collision>
    <visual name="f-adrt__visual">
      <origin rpy="0  0  0" xyz="0  0  0"/>
      <geometry>
        <cylinder length="0.25" radius="0.3"/>
      </geometry>
    </visual>
  </link>

</robot>
