<?xml version="1.0"?>



<robot name="adrt" xmlns:xacro="http://www.ros.org/wiki/xacro">


    <xacro:property name="cameraSize" value="0.05" />
    <xacro:property name="cameraMass" value="0.1" />

    <xacro:include filename="$(find adrt_description)/urdf/materials.xacro"/>
    <xacro:include filename="$(find adrt_description)/urdf/adrt.gazebo"/>

  <joint name="left_wheel_joint" type="continuous">
  <origin xyz="0 0.125 -0.05" rpy="0.0 0.0 0.0"/>
  <parent link="chassis"/>
  <child link="left_wheel"/>
  <axis xyz="0.0 1 0.0" rpy="0 0 0"/>
  <limit effort="100000" velocity="1000"/>
  <joint_properties damping="1" friction="1" />
</joint>
  
    <joint name="right_wheel_joint" type="continuous">
  <origin xyz="0 -0.125 -0.05" rpy="0.0 0.0 0.0"/>
  <parent link="chassis"/>
  <child link="right_wheel"/>
  <axis xyz="0.0 1 0.0" rpy="0 0 0"/>
  <limit effort="100000" velocity="1000"/>
  <joint_properties damping="1" friction="1" />
</joint>
  
<!-- chassis -->
  <link name="chassis">
    <inertial>
      <mass value="15.0"/>
      <origin rpy="0  0  0" xyz="0  0  0"/>
      <inertia ixx="0.1" ixy="0" ixz="0" iyy="0.1" iyz="0" izz="0.1"/>
    </inertial>
    <collision name="chassis_collision">
      <origin rpy="0 0 0" xyz="0 0 0"/>
      <geometry>
        <box size=".4 .2 0.1"/>
      </geometry>
    </collision>
    <visual name="chassis_visual">
      <origin rpy="0 0 0" xyz="0 0 0"/>
      <geometry>
        <box size=".4 .2 0.1"/>
      </geometry>
    </visual>

    <collision name="caster_wheel_collision">
      <origin xyz="-0.15 0.0 -0.05" rpy="0.0 0.0 0.0"/>
      <geometry>
        <sphere radius="0.05"/>
      </geometry>
      <surface>
        <friction>
          <ode>
            <mu>0</mu>
            <mu2>0</mu2>
            <slip1>1.0</slip1>
            <slip2>1.0</slip2>
          </ode>
        </friction>
      </surface>
    </collision>

    <visual name="caster_wheel_visual">
      <origin xyz="-0.15 0.0 -0.05" rpy="0.0 0.0 0.0"/>
      <geometry>
        <sphere radius="0.05"/>
      </geometry>
    </visual>

        <collision name="back_caster_wheel_collision">
      <origin xyz="0.15 0.0 -0.05" rpy="0.0 0.0 0.0"/>
      <geometry>
        <sphere radius="0.05"/>
      </geometry>
      <surface>
        <friction>
          <ode>
            <mu>0</mu>
            <mu2>0</mu2>
            <slip1>1.0</slip1>
            <slip2>1.0</slip2>
          </ode>
        </friction>
      </surface>
    </collision>

    <visual name="back_caster_wheel_visual">
      <origin xyz="0.15 0.0 -0.05" rpy="0.0 0.0 0.0"/>
      <geometry>
        <sphere radius="0.05"/>
      </geometry>
    </visual>

  </link>

  <link name="left_wheel">
    <inertial>
      <origin xyz="0.0 0.0 0" rpy="1.5707 0 0"/>
      <mass value="5"/>
      <inertia ixx="0.1" ixy="0.0" ixz="0.0" iyy="0.1" iyz="0.0" izz="0.1"/>
    </inertial>
    <visual name="">
      <origin xyz="0.0 0.0 0" rpy="1.5707 0 0"/>
      <geometry>
        <cylinder radius="0.05" length="0.05"/>
      </geometry>
    </visual>
    <collision>
      <origin xyz="0 0.0 0" rpy="1.5707 0 0"/>
      <geometry>
        <cylinder radius="0.05" length="0.05"/>
      </geometry>
    </collision>
  </link>


<link name="right_wheel">
    <inertial>
      <origin xyz="0.0 0.0 0" rpy="1.5707 0 0"/>
      <mass value="5"/>
      <inertia ixx="0.1" ixy="0.0" ixz="0.0" iyy="0.1" iyz="0.0" izz="0.1"/>
    </inertial>
    <visual name="">
      <origin xyz="0.0 0.0 0" rpy="1.5707 0 0"/>
      <geometry>
        <cylinder radius="0.05" length="0.05"/>
      </geometry>
    </visual>
    <collision>
      <origin xyz="0 0.0 0" rpy="1.5707 0 0"/>
      <geometry>
        <cylinder radius="0.05" length="0.05"/>
      </geometry>
    </collision>
  </link>


  <!-- camera_joint -->
  <joint name="camera_joint" type="fixed">
    <axis xyz="0 1 0" />
    <origin xyz="0.2 0 0" rpy="0 0 0"/>
    <parent link="chassis"/>
    <child link="camera"/>
  </joint>
  <!-- camera_joint -->

  <!-- Camera_link-->
  <link name="camera">
    <collision>
      <origin xyz="0 0 0" rpy="0 0 0"/>
      <geometry>
    <box size="${cameraSize} ${cameraSize} ${cameraSize}"/>
      </geometry>
    </collision>

    <visual>
      <origin xyz="0 0 0" rpy="0 0 0"/>
      <geometry>
    <box size="${cameraSize} ${cameraSize} ${cameraSize}"/>
      </geometry>
      <material name="green"/>
    </visual>

    <inertial>
      <mass value="${cameraMass}" />
      <origin xyz="0 0 0" rpy="0 0 0"/>
      <box_inertia m="${cameraMass}" x="${cameraSize}" y="${cameraSize}" z="${cameraSize}" />
      <inertia ixx="1e-6" ixy="0" ixz="0" iyy="1e-6" iyz="0" izz="1e-6" />
    </inertial>
  </link>
  <!-- Camera_link -->


<!-- hokuyo_joint -->
<joint name="hokuyo_joint" type="fixed">
    <axis xyz="0 1 0" />
    <origin xyz="0.15 0 0.1" rpy="0 0 0"/>
    <parent link="chassis"/>
    <child link="hokuyo_link"/>
  </joint>
<!-- hokuyo_joint -->


<!-- Hokuyo_link -->
  <link name="hokuyo_link">
    <collision>
      <origin xyz="0 0 0" rpy="0 0 0"/>
      <geometry>
    <box size="0.1 0.1 0.1"/>
      </geometry>
    </collision>

    <visual>
      <origin xyz="0 0 0" rpy="0 0 0"/>
      <geometry>
          <box size="0.1 0.1 0.1"/>
      </geometry>
    </visual>

    <inertial>
      <mass value="1e-5" />
      <origin xyz="0 0 0" rpy="0 0 0"/>
      <inertia ixx="1e-6" ixy="0" ixz="0" iyy="1e-6" iyz="0" izz="1e-6" />
    </inertial>
  </link>
<!-- hokuyo_link -->

<!--imu_link
  <link name="imu_link">
    <collision>
      <origin xyz="0 0 0" rpy="0 0 0"/>
      <geometry>
    <box size="${cameraSize} ${cameraSize} ${cameraSize}"/>
      </geometry>
    </collision>

    <visual>
      <origin xyz="0 0 0" rpy="0 0 0"/>
      <geometry>
    <box size="${cameraSize} ${cameraSize} ${cameraSize}"/>
      </geometry>
      <material name="green"/>
    </visual>

    <inertial>
      <mass value="${cameraMass}" />
      <origin xyz="0 0 0" rpy="0 0 0"/>
      <box_inertia m="${cameraMass}" x="${cameraSize}" y="${cameraSize}" z="${cameraSize}" />
      <inertia ixx="1e-6" ixy="0" ixz="0" iyy="1e-6" iyz="0" izz="1e-6" />
    </inertial>
  </link>
  imu_link -->
 
  <!-- imu_joint
  <joint name="imu_joint" type="fixed">
    <axis xyz="0 1 0" />
    <origin xyz="-0.2 0 0" rpy="0 0 0"/>
    <parent link="chassis"/>
    <child link="imu_link"/>
  </joint>
   imu_joint -->

</robot>
