<?xml version="1.0" ?>
<robot name="adrt">
  <joint name="adrt__link_0_JOINT_0" type="revolute">
    <parent link="adrt__link_0"/>
    <child link="adrt__link_1"/>
    <origin rpy="1.5707  0      0" xyz="0.55    -0.62502  0"/>
    <axis xyz="0.00000000e+00   1.00000000e+00   9.00000000e-05"/>
    <limit effort="-1.0" lower="-1.79769e+308" upper="1.79769e+308" velocity="-1.0"/>
  </joint>
  <joint name="adrt__link_0_JOINT_1" type="revolute">
    <parent link="adrt__link_0"/>
    <child link="adrt__link_1_clone"/>
    <origin rpy="1.5707  0      0" xyz="0.55     0.62502  0"/>
    <axis xyz="0.00000000e+00   1.00000000e+00   9.00000000e-05"/>
    <limit effort="-1.0" lower="-1.79769e+308" upper="1.79769e+308" velocity="-1.0"/>
  </joint>
  <joint name="adrt__link_0_JOINT_2" type="ball">
    <parent link="adrt__link_0"/>
    <child link="adrt__link_2"/>
    <origin rpy="0  0  0" xyz="-0.95  0   -0.1"/>
    <axis xyz="0  0  0"/>
    <limit effort="0" lower="0" upper="0" velocity="0"/>
  </joint>
  <link name="adrt__link_0">
    <inertial>
      <mass value="1"/>
      <origin rpy="0  0  0" xyz="0  0  0"/>
      <inertia ixx="0.166667" ixy="0" ixz="0" iyy="0.166667" iyz="0" izz="0.166667"/>
    </inertial>
    <collision name="adrt__collision">
      <origin rpy="0  0  0" xyz="-0.15  0    0.1"/>
      <geometry>
        <box size="2 1 0.5"/>
      </geometry>
    </collision>
    <visual name="adrt__visual">
      <origin rpy="0  0  0" xyz="-0.15  0    0.1"/>
      <geometry>
        <box size="2 1 0.5"/>
      </geometry>
    </visual>
  </link>
  <link name="adrt__link_1">
    <inertial>
      <mass value="1"/>
      <origin rpy="0  0  0" xyz="0  0  0"/>
      <inertia ixx="0.145833" ixy="0" ixz="0" iyy="0.145833" iyz="0" izz="0.125"/>
    </inertial>
    <collision name="adrt__collision">
      <origin rpy="0  0  0" xyz="0  0  0"/>
      <geometry>
        <cylinder length="0.25" radius="0.3"/>
      </geometry>
    </collision>
    <visual name="adrt__visual">
      <origin rpy="0  0  0" xyz="0  0  0"/>
      <geometry>
        <cylinder length="0.25" radius="0.3"/>
      </geometry>
    </visual>
  </link>
  <link name="adrt__link_1_clone">
    <inertial>
      <mass value="1"/>
      <origin rpy="0  0  0" xyz="0  0  0"/>
      <inertia ixx="0.145833" ixy="0" ixz="0" iyy="0.145833" iyz="0" izz="0.125"/>
    </inertial>
    <collision name="adrt__collision">
      <origin rpy="0  0  0" xyz="0  0  0"/>
      <geometry>
        <cylinder length="0.25" radius="0.3"/>
      </geometry>
    </collision>
    <visual name="adrt__visual">
      <origin rpy="0  0  0" xyz="0  0  0"/>
      <geometry>
        <cylinder length="0.25" radius="0.3"/>
      </geometry>
    </visual>
  </link>
  <link name="adrt__link_2">
    <inertial>
      <mass value="1"/>
      <origin rpy="0  0  0" xyz="0  0  0"/>
      <inertia ixx="0.1" ixy="0" ixz="0" iyy="0.1" iyz="0" izz="0.1"/>
    </inertial>
    <collision name="adrt__collision">
      <origin rpy="0  0  0" xyz="0  0  0"/>
      <geometry>
        <sphere radius="0.2"/>
      </geometry>
    </collision>
    <visual name="adrt__visual">
      <origin rpy="0  0  0" xyz="0  0  0"/>
      <geometry>
        <sphere radius="0.2"/>
      </geometry>
    </visual>
  </link>

  
</robot>
